Workbook

Sheet Resumo
A1: Auditoria de fatura de frete - Resumo
A2: Base 100% fictícia (jan-set/2026). Mesma regra do SQL, escrita em fórmulas.
A4: Tolerância de arredondamento (R$) | B4: 1 | C4: <- célula editável: diferenças até esse valor contam como OK
A6: Indicador | B6: Valor
A7: Faturas analisadas | B7: =COUNTA(Detalhe!$A$2:$A$621) -> 620
A8: Faturas acima da tabela | B8: =COUNTIF(Detalhe!$P$2:$P$621,"ACIMA DA TABELA") -> 104
A9: Valor cobrado a mais (R$) | B9: =SUMIFS(Detalhe!$N$2:$N$621,Detalhe!$P$2:$P$621,"ACIMA DA TABELA") -> 20246.94
A10: Excesso sobre o valor de tabela (%) | B10: =B9/SUM(Detalhe!$M$2:$M$621) -> 0.028320365
A11: Fretes em rota sem tarifa no contrato | B11: =COUNTIF(Detalhe!$P$2:$P$621,"SEM TARIFA NO CONTRATO") -> 12
A12: Valor desses fretes sem tarifa (R$) | B12: =SUMIFS(Detalhe!$L$2:$L$621,Detalhe!$P$2:$P$621,"SEM TARIFA NO CONTRATO") -> 22716.45
A13: Cobranças em duplicidade (R$ a mais) | B13: =SUM(Duplicidades!$F$2:$F$9) -> 6466.16
A14: Potencial a recuperar (R$) | B14: =B9+B13 -> 26713.1
A15: Potencial a recuperar = excesso acima da tabela + duplicidades. Nesta base as duplicadas estão dentro da tabela, então não há dupla contagem.
A17: Por transportadora
A18: Transportadora | B18: Faturas | C18: Acima da tabela | D18: % acima | E18: Excesso (R$)
A19: Veloz Cargas | B19: =COUNTIFS(Detalhe!$C$2:$C$621,A19,Detalhe!$P$2:$P$621,"<>SEM TARIFA NO CONTRATO") -> 138 | C19: =COUNTIFS(Detalhe!$C$2:$C$621,A19,Detalhe!$P$2:$P$621,"ACIMA DA TABELA") -> 43 | D19: =IF(B19=0,0,C19/B19) -> 0.3115942 | E19: =SUMIFS(Detalhe!$N$2:$N$621,Detalhe!$C$2:$C$621,A19,Detalhe!$P$2:$P$621,"ACIMA DA TABELA") -> 11304.31
A20: Atlântico Logística | B20: =COUNTIFS(Detalhe!$C$2:$C$621,A20,Detalhe!$P$2:$P$621,"<>SEM TARIFA NO CONTRATO") -> 79 | C20: =COUNTIFS(Detalhe!$C$2:$C$621,A20,Detalhe!$P$2:$P$621,"ACIMA DA TABELA") -> 37 | D20: =IF(B20=0,0,C20/B20) -> 0.46835443 | E20: =SUMIFS(Detalhe!$N$2:$N$621,Detalhe!$C$2:$C$621,A20,Detalhe!$P$2:$P$621,"ACIMA DA TABELA") -> 7294.88
A21: Norte Sul Fretes | B21: =COUNTIFS(Detalhe!$C$2:$C$621,A21,Detalhe!$P$2:$P$621,"<>SEM TARIFA NO CONTRATO") -> 72 | C21: =COUNTIFS(Detalhe!$C$2:$C$621,A21,Detalhe!$P$2:$P$621,"ACIMA DA TABELA") -> 6 | D21: =IF(B21=0,0,C21/B21) -> 0.083333333 | E21: =SUMIFS(Detalhe!$N$2:$N$621,Detalhe!$C$2:$C$621,A21,Detalhe!$P$2:$P$621,"ACIMA DA TABELA") -> 781.46
A22: TransLog Express | B22: =COUNTIFS(Detalhe!$C$2:$C$621,A22,Detalhe!$P$2:$P$621,"<>SEM TARIFA NO CONTRATO") -> 164 | C22: =COUNTIFS(Detalhe!$C$2:$C$621,A22,Detalhe!$P$2:$P$621,"ACIMA DA TABELA") -> 9 | D22: =IF(B22=0,0,C22/B22) -> 0.054878049 | E22: =SUMIFS(Detalhe!$N$2:$N$621,Detalhe!$C$2:$C$621,A22,Detalhe!$P$2:$P$621,"ACIMA DA TABELA") -> 451.04
A23: RodoFácil Transportes | B23: =COUNTIFS(Detalhe!$C$2:$C$621,A23,Detalhe!$P$2:$P$621,"<>SEM TARIFA NO CONTRATO") -> 155 | C23: =COUNTIFS(Detalhe!$C$2:$C$621,A23,Detalhe!$P$2:$P$621,"ACIMA DA TABELA") -> 9 | D23: =IF(B23=0,0,C23/B23) -> 0.058064516 | E23: =SUMIFS(Detalhe!$N$2:$N$621,Detalhe!$C$2:$C$621,A23,Detalhe!$P$2:$P$621,"ACIMA DA TABELA") -> 415.25
A25: Por mês de emissão (2026)
A26: Mês (nº) | B26: Faturas | C26: Acima da tabela | D26: Excesso (R$)
A27: 1 | B27: =COUNTIFS(Detalhe!$E$2:$E$621,A27,Detalhe!$P$2:$P$621,"<>SEM TARIFA NO CONTRATO") -> 60 | C27: =COUNTIFS(Detalhe!$E$2:$E$621,A27,Detalhe!$P$2:$P$621,"ACIMA DA TABELA") -> 9 | D27: =SUMIFS(Detalhe!$N$2:$N$621,Detalhe!$E$2:$E$621,A27,Detalhe!$P$2:$P$621,"ACIMA DA TABELA") -> 2324.66
A28: 2 | B28: =COUNTIFS(Detalhe!$E$2:$E$621,A28,Detalhe!$P$2:$P$621,"<>SEM TARIFA NO CONTRATO") -> 47 | C28: =COUNTIFS(Detalhe!$E$2:$E$621,A28,Detalhe!$P$2:$P$621,"ACIMA DA TABELA") -> 8 | D28: =SUMIFS(Detalhe!$N$2:$N$621,Detalhe!$E$2:$E$621,A28,Detalhe!$P$2:$P$621,"ACIMA DA TABELA") -> 1083.75
A29: 3 | B29: =COUNTIFS(Detalhe!$E$2:$E$621,A29,Detalhe!$P$2:$P$621,"<>SEM TARIFA NO CONTRATO") -> 88 | C29: =COUNTIFS(Detalhe!$E$2:$E$621,A29,Detalhe!$P$2:$P$621,"ACIMA DA TABELA") -> 13 | D29: =SUMIFS(Detalhe!$N$2:$N$621,Detalhe!$E$2:$E$621,A29,Detalhe!$P$2:$P$621,"ACIMA DA TABELA") -> 2105.87
A30: 4 | B30: =COUNTIFS(Detalhe!$E$2:$E$621,A30,Detalhe!$P$2:$P$621,"<>SEM TARIFA NO CONTRATO") -> 67 | C30: =COUNTIFS(Detalhe!$E$2:$E$621,A30,Detalhe!$P$2:$P$621,"ACIMA DA TABELA") -> 7 | D30: =SUMIFS(Detalhe!$N$2:$N$621,Detalhe!$E$2:$E$621,A30,Detalhe!$P$2:$P$621,"ACIMA DA TABELA") -> 1084.08
A31: 5 | B31: =COUNTIFS(Detalhe!$E$2:$E$621,A31,Detalhe!$P$2:$P$621,"<>SEM TARIFA NO CONTRATO") -> 79 | C31: =COUNTIFS(Detalhe!$E$2:$E$621,A31,Detalhe!$P$2:$P$621,"ACIMA DA TABELA") -> 15 | D31: =SUMIFS(Detalhe!$N$2:$N$621,Detalhe!$E$2:$E$621,A31,Detalhe!$P$2:$P$621,"ACIMA DA TABELA") -> 2663.86
A32: 6 | B32: =COUNTIFS(Detalhe!$E$2:$E$621,A32,Detalhe!$P$2:$P$621,"<>SEM TARIFA NO CONTRATO") -> 76 | C32: =COUNTIFS(Detalhe!$E$2:$E$621,A32,Detalhe!$P$2:$P$621,"ACIMA DA TABELA") -> 12 | D32: =SUMIFS(Detalhe!$N$2:$N$621,Detalhe!$E$2:$E$621,A32,Detalhe!$P$2:$P$621,"ACIMA DA TABELA") -> 4207.7
A33: 7 | B33: =COUNTIFS(Detalhe!$E$2:$E$621,A33,Detalhe!$P$2:$P$621,"<>SEM TARIFA NO CONTRATO") -> 71 | C33: =COUNTIFS(Detalhe!$E$2:$E$621,A33,Detalhe!$P$2:$P$621,"ACIMA DA TABELA") -> 14 | D33: =SUMIFS(Detalhe!$N$2:$N$621,Detalhe!$E$2:$E$621,A33,Detalhe!$P$2:$P$621,"ACIMA DA TABELA") -> 3284.15
A34: 8 | B34: =COUNTIFS(Detalhe!$E$2:$E$621,A34,Detalhe!$P$2:$P$621,"<>SEM TARIFA NO CONTRATO") -> 66 | C34: =COUNTIFS(Detalhe!$E$2:$E$621,A34,Detalhe!$P$2:$P$621,"ACIMA DA TABELA") -> 17 | D34: =SUMIFS(Detalhe!$N$2:$N$621,Detalhe!$E$2:$E$621,A34,Detalhe!$P$2:$P$621,"ACIMA DA TABELA") -> 2723.8
A35: 9 | B35: =COUNTIFS(Detalhe!$E$2:$E$621,A35,Detalhe!$P$2:$P$621,"<>SEM TARIFA NO CONTRATO") -> 54 | C35: =COUNTIFS(Detalhe!$E$2:$E$621,A35,Detalhe!$P$2:$P$621,"ACIMA DA TABELA") -> 9 | D35: =SUMIFS(Detalhe!$N$2:$N$621,Detalhe!$E$2:$E$621,A35,Detalhe!$P$2:$P$621,"ACIMA DA TABELA") -> 769.07

Sheet Detalhe
A1: Nº fatura | B1: CT-e | C1: Transportadora | D1: Data emissão | E1: Mês (nº) | F1: Rota | G1: Origem | H1: Destino | I1: Peso (kg) | J1: Tarifa (R$/kg) | K1: Frete mínimo (R$) | L1: Valor cobrado (R$) | M1: Valor tabela (R$) | N1: Diferença (R$) | O1: Diferença (%) | P1: Status
A2: NF-100001 | B2: CTE-0000001 | C2: TransLog Express | D2: 46023 | E2: =MONTH(D2) -> 1 | F2: R09 | G2: Curitiba/PR | H2: São Paulo/SP | I2: 3648.4 | J2: 0.856 | K2: 109.2 | L2: 3123.4 | M2: =IF(J2="","",ROUND(MAX(I2*J2,K2),2)) -> 3123.03 | N2: =IF(M2="","",ROUND(L2-M2,2)) -> 0.37 | O2: =IF(M2="","",N2/M2) -> 0.00011847469 | P2: =IF(M2="","SEM TARIFA NO CONTRATO",IF(N2>Resumo!$B$4,"ACIMA DA TABELA",IF(N2<-Resumo!$B$4,"ABAIXO DA TABELA","OK"))) -> OK
A3: NF-100002 | B3: CTE-0000002 | C3: Veloz Cargas | D3: 46023 | E3: =MONTH(D3) -> 1 | F3: R07 | G3: Campinas/SP | H3: Recife/PE | I3: 798 | J3: 4.884 | K3: 415.8 | L3: 4383.72 | M3: =IF(J3="","",ROUND(MAX(I3*J3,K3),2)) -> 3897.43 | N3: =IF(M3="","",ROUND(L3-M3,2)) -> 486.29 | O3: =IF(M3="","",N3/M3) -> 0.12477197 | P3: =IF(M3="","SEM TARIFA NO CONTRATO",IF(N3>Resumo!$B$4,"ACIMA DA TABELA",IF(N3<-Resumo!$B$4,"ABAIXO DA TABELA","OK"))) -> ACIMA DA TABELA
A4: NF-100003 | B4: CTE-0000003 | C4: RodoFácil Transportes | D4: 46023 | E4: =MONTH(D4) -> 1 | F4: R09 | G4: Curitiba/PR | H4: São Paulo/SP | I4: 277 | J4: 0.8132 | K4: 103.74 | L4: 225.39 | M4: =IF(J4="","",ROUND(MAX(I4*J4,K4),2)) -> 225.26 | N4: =IF(M4="","",ROUND(L4-M4,2)) -> 0.13 | O4: =IF(M4="","",N4/M4) -> 0.00057711089 | P4: =IF(M4="","SEM TARIFA NO CONTRATO",IF(N4>Resumo!$B$4,"ACIMA DA TABELA",IF(N4<-Resumo!$B$4,"ABAIXO DA TABELA","OK"))) -> OK
A5: NF-100004 | B5: CTE-0000004 | C5: RodoFácil Transportes | D5: 46024 | E5: =MONTH(D5) -> 1 | F5: R04 | G5: Campinas/SP | H5: Curitiba/PR | I5: 237.1 | J5: 0.8132 | K5: 103.74 | L5: 192.55 | M5: =IF(J5="","",ROUND(MAX(I5*J5,K5),2)) -> 192.81 | N5: =IF(M5="","",ROUND(L5-M5,2)) -> -0.26 | O5: =IF(M5="","",N5/M5) -> -0.0013484778 | P5: =IF(M5="","SEM TARIFA NO CONTRATO",IF(N5>Resumo!$B$4,"ACIMA DA TABELA",IF(N5<-Resumo!$B$4,"ABAIXO DA TABELA","OK"))) -> OK
A6: NF-100005 | B6: CTE-0000005 | C6: Atlântico Logística | D6: 46024 | E6: =MONTH(D6) -> 1 | F6: R04 | G6: Campinas/SP | H6: Curitiba/PR | I6: 402.1 | J6: 0.8988 | K6: 114.66 | L6: 361.35 | M6: =IF(J6="","",ROUND(MAX(I6*J6,K6),2)) -> 361.41 | N6: =IF(M6="","",ROUND(L6-M6,2)) -> -0.06 | O6: =IF(M6="","",N6/M6) -> -0.00016601644 | P6: =IF(M6="","SEM TARIFA NO CONTRATO",IF(N6>Resumo!$B$4,"ACIMA DA TABELA",IF(N6<-Resumo!$B$4,"ABAIXO DA TABELA","OK"))) -> OK
A7: NF-100006 | B7: CTE-0000006 | C7: RodoFácil Transportes | D7: 46025 | E7: =MONTH(D7) -> 1 | F7: R02 | G7: Campinas/SP | H7: Rio de Janeiro/RJ | I7: 53.7 | J7: 0.95 | K7: 114 | L7: 114.16 | M7: =IF(J7="","",ROUND(MAX(I7*J7,K7),2)) -> 114 | N7: =IF(M7="","",ROUND(L7-M7,2)) -> 0.16 | O7: =IF(M7="","",N7/M7) -> 0.0014035088 | P7: =IF(M7="","SEM TARIFA NO CONTRATO",IF(N7>Resumo!$B$4,"ACIMA DA TABELA",IF(N7<-Resumo!$B$4,"ABAIXO DA TABELA","OK"))) -> OK
A8: NF-100007 | B8: CTE-0000007 | C8: Norte Sul Fretes | D8: 46026 | E8: =MONTH(D8) -> 1 | F8: R04 | G8: Campinas/SP | H8: Curitiba/PR | I8: 631.6 | J8: 0.7875 | K8: 100.46 | L8: 497.49 | M8: =IF(J8="","",ROUND(MAX(I8*J8,K8),2)) -> 497.39 | N8: =IF(M8="","",ROUND(L8-M8,2)) -> 0.1 | O8: =IF(M8="","",N8/M8) -> 0.00020104948 | P8: =IF(M8="","SEM TARIFA NO CONTRATO",IF(N8>Resumo!$B$4,"ACIMA DA TABELA",IF(N8<-Resumo!$B$4,"ABAIXO DA TABELA","OK"))) -> OK
A9: NF-100008 | B9: CTE-0000008 | C9: TransLog Express | D9: 46027 | E9: =MONTH(D9) -> 1 | F9: R05 | G9: Campinas/SP | H9: Porto Alegre/RS | I9: 604.1 | J9: 1.96 | K9: 192 | L9: 1183.92 | M9: =IF(J9="","",ROUND(MAX(I9*J9,K9),2)) -> 1184.04 | N9: =IF(M9="","",ROUND(L9-M9,2)) -> -0.12 | O9: =IF(M9="","",N9/M9) -> -0.00010134793 | P9: =IF(M9="","SEM TARIFA NO CONTRATO",IF(N9>Resumo!$B$4,"ACIMA DA TABELA",IF(N9<-Resumo!$B$4,"ABAIXO DA TABELA","OK"))) -> OK
A10: NF-100009 | B10: CTE-0000009 | C10: Veloz Cargas | D10: 46028 | E10: =MONTH(D10) -> 1 | F10: R07 | G10: Campinas/SP | H10: Recife/PE | I10: 277.3 | J10: 4.884 | K10: 415.8 | L10: 1354.12 | M10: =IF(J10="","",ROUND(MAX(I10*J10,K10),2)) -> 1354.33 | N10: =IF(M10="","",ROUND(L10-M10,2)) -> -0.21 | O10: =IF(M10="","",N10/M10) -> -0.00015505822 | P10: =IF(M10="","SEM TARIFA NO CONTRATO",IF(N10>Resumo!$B$4,"ACIMA DA TABELA",IF(N10<-Resumo!$B$4,"ABAIXO DA TABELA","OK"))) -> OK
A11: NF-100010 | B11: CTE-0000010 | C11: Atlântico Logística | D11: 46029 | E11: =MONTH(D11) -> 1 | F11: R03 | G11: Campinas/SP | H11: Belo Horizonte/MG | I11: 1444.3 | J11: 1.2012 | K11: 137.34 | L11: 1734.62 | M11: =IF(J11="","",ROUND(MAX(I11*J11,K11),2)) -> 1734.89 | N11: =IF(M11="","",ROUND(L11-M11,2)) -> -0.27 | O11: =IF(M11="","",N11/M11) -> -0.00015562946 | P11: =IF(M11="","SEM TARIFA NO CONTRATO",IF(N11>Resumo!$B$4,"ACIMA DA TABELA",IF(N11<-Resumo!$B$4,"ABAIXO DA TABELA","OK"))) -> OK
A12: NF-100011 | B12: CTE-0000011 | C12: TransLog Express | D12: 46030 | E12: =MONTH(D12) -> 1 | F12: R03 | G12: Campinas/SP | H12: Belo Horizonte/MG | I12: 517.4 | J12: 1.144 | K12: 130.8 | L12: 591.51 | M12: =IF(J12="","",ROUND(MAX(I12*J12,K12),2)) -> 591.91 | N12: =IF(M12="","",ROUND(L12-M12,2)) -> -0.4 | O12: =IF(M12="","",N12/M12) -> -0.00067577841 | P12: =IF(M12="","SEM TARIFA NO CONTRATO",IF(N12>Resumo!$B$4,"ACIMA DA TABELA",IF(N12<-Resumo!$B$4,"ABAIXO DA TABELA","OK"))) -> OK
A13: NF-100012 | B13: CTE-0000012 | C13: Norte Sul Fretes | D13: 46031 | E13: =MONTH(D13) -> 1 | F13: R01 | G13: Campinas/SP | H13: São Paulo/SP | I13: 565 | J13: 0.3312 | K13: 66.24 | L13: 186.9 | M13: =IF(J13="","",ROUND(MAX(I13*J13,K13),2)) -> 187.13 | N13: =IF(M13="","",ROUND(L13-M13,2)) -> -0.23 | O13: =IF(M13="","",N13/M13) -> -0.0012290921 | P13: =IF(M13="","SEM TARIFA NO CONTRATO",IF(N13>Resumo!$B$4,"ACIMA DA TABELA",IF(N13<-Resumo!$B$4,"ABAIXO DA TABELA","OK"))) -> OK
... A23: NF-100022 | B23: CTE-0000022 | C23: Veloz Cargas | D23: 46037 | E23: =MONTH(D23) -> 1 | F23: R03 | G23: Campinas/SP | H23: Belo Horizonte/MG | I23: 161.4 | J23: 1.2584 | K23: 143.88 | L23: 203.44 | M23: =IF(J23="","",ROUND(MAX(I23*J23,K23),2)) -> 203.11 | N23: =IF(M23="","",ROUND(L23-M23,2)) -> 0.33 | O23: =IF(M23="","",N23/M23) -> 0.0016247354 | P23: =IF(M23="","SEM TARIFA NO CONTRATO",IF(N23>Resumo!$B$4,"ACIMA DA TABELA",IF(N23<-Resumo!$B$4,"ABAIXO DA TABELA","OK"))) -> OK
A24: NF-100023 | B24: CTE-0000023 | C24: Veloz Cargas | D24: 46037 | E24: =MONTH(D24) -> 1 | F24: R10 | G24: Curitiba/PR | H24: Porto Alegre/RS | I24: 1214.7 | L24: 2004.26 | M24: =IF(J24="","",ROUND(MAX(I24*J24,K24),2)) | N24: =IF(M24="","",ROUND(L24-M24,2)) | O24: =IF(M24="","",N24/M24) | P24: =IF(M24="","SEM TARIFA NO CONTRATO",IF(N24>Resumo!$B$4,"ACIMA DA TABELA",IF(N24<-Resumo!$B$4,"ABAIXO DA TABELA","OK"))) -> SEM TARIFA NO CONTRATO
A25: NF-100024 | B25: CTE-0000024 | C25: Veloz Cargas | D25: 46038 | E25: =MONTH(D25) -> 1 | F25: R02 | G25: Campinas/SP | H25: Rio de Janeiro/RJ | I25: 217.6 | J25: 1.1 | K25: 132 | L25: 239.44 | M25: =IF(J25="","",ROUND(MAX(I25*J25,K25),2)) -> 239.36 | N25: =IF(M25="","",ROUND(L25-M25,2)) -> 0.08 | O25: =IF(M25="","",N25/M25) -> 0.0003342246 | P25: =IF(M25="","SEM TARIFA NO CONTRATO",IF(N25>Resumo!$B$4,"ACIMA DA TABELA",IF(N25<-Resumo!$B$4,"ABAIXO DA TABELA","OK"))) -> OK
A26: NF-100025 | B26: CTE-0000025 | C26: Veloz Cargas | D26: 46039 | E26: =MONTH(D26) -> 1 | F26: R05 | G26: Campinas/SP | H26: Porto Alegre/RS | I26: 119.7 | J26: 2.156 | K26: 211.2 | L26: 258.24 | M26: =IF(J26="","",ROUND(MAX(I26*J26,K26),2)) -> 258.07 | N26: =IF(M26="","",ROUND(L26-M26,2)) -> 0.17 | O26: =IF(M26="","",N26/M26) -> 0.000658736 | P26: =IF(M26="","SEM TARIFA NO CONTRATO",IF(N26>Resumo!$B$4,"ACIMA DA TABELA",IF(N26<-Resumo!$B$4,"ABAIXO DA TABELA","OK"))) -> OK
A27: NF-100026 | B27: CTE-0000026 | C27: Veloz Cargas | D27: 46039 | E27: =MONTH(D27) -> 1 | F27: R05 | G27: Campinas/SP | H27: Porto Alegre/RS | I27: 717.2 | J27: 2.156 | K27: 211.2 | L27: 1697.86 | M27: =IF(J27="","",ROUND(MAX(I27*J27,K27),2)) -> 1546.28 | N27: =IF(M27="","",ROUND(L27-M27,2)) -> 151.58 | O27: =IF(M27="","",N27/M27) -> 0.098028818 | P27: =IF(M27="","SEM TARIFA NO CONTRATO",IF(N27>Resumo!$B$4,"ACIMA DA TABELA",IF(N27<-Resumo!$B$4,"ABAIXO DA TABELA","OK"))) -> ACIMA DA TABELA
A28: NF-100027 | B28: CTE-0000027 | C28: TransLog Express | D28: 46039 | E28: =MONTH(D28) -> 1 | F28: R09 | G28: Curitiba/PR | H28: São Paulo/SP | I28: 179.3 | J28: 0.856 | K28: 109.2 | L28: 159.85 | M28: =IF(J28="","",ROUND(MAX(I28*J28,K28),2)) -> 153.48 | N28: =IF(M28="","",ROUND(L28-M28,2)) -> 6.37 | O28: =IF(M28="","",N28/M28) -> 0.041503779 | P28: =IF(M28="","SEM TARIFA NO CONTRATO",IF(N28>Resumo!$B$4,"ACIMA DA TABELA",IF(N28<-Resumo!$B$4,"ABAIXO DA TABELA","OK"))) -> ACIMA DA TABELA
A29: NF-100028 | B29: CTE-0000028 | C29: Veloz Cargas | D29: 46039 | E29: =MONTH(D29) -> 1 | F29: R08 | G29: Campinas/SP | H29: Goiânia/GO | I29: 242.1 | J29: 1.8568 | K29: 188.76 | L29: 449.58 | M29: =IF(J29="","",ROUND(MAX(I29*J29,K29),2)) -> 449.53 | N29: =IF(M29="","",ROUND(L29-M29,2)) -> 0.05 | O29: =IF(M29="","",N29/M29) -> 0.00011122728 | P29: =IF(M29="","SEM TARIFA NO CONTRATO",IF(N29>Resumo!$B$4,"ACIMA DA TABELA",IF(N29<-Resumo!$B$4,"ABAIXO DA TABELA","OK"))) -> OK
A30: NF-100029 | B30: CTE-0000022 | C30: Veloz Cargas | D30: 46040 | E30: =MONTH(D30) -> 1 | F30: R03 | G30: Campinas/SP | H30: Belo Horizonte/MG | I30: 161.4 | J30: 1.2584 | K30: 143.88 | L30: 203.44 | M30: =IF(J30="","",ROUND(MAX(I30*J30,K30),2)) -> 203.11 | N30: =IF(M30="","",ROUND(L30-M30,2)) -> 0.33 | O30: =IF(M30="","",N30/M30) -> 0.0016247354 | P30: =IF(M30="","SEM TARIFA NO CONTRATO",IF(N30>Resumo!$B$4,"ACIMA DA TABELA",IF(N30<-Resumo!$B$4,"ABAIXO DA TABELA","OK"))) -> OK
A31: NF-100030 | B31: CTE-0000029 | C31: Veloz Cargas | D31: 46040 | E31: =MONTH(D31) -> 1 | F31: R06 | G31: Campinas/SP | H31: Salvador/BA | I31: 231.5 | J31: 3.6696 | K31: 324.72 | L31: 849.63 | M31: =IF(J31="","",ROUND(MAX(I31*J31,K31),2)) -> 849.51 | N31: =IF(M31="","",ROUND(L31-M31,2)) -> 0.12 | O31: =IF(M31="","",N31/M31) -> 0.0001412579 | P31: =IF(M31="","SEM TARIFA NO CONTRATO",IF(N31>Resumo!$B$4,"ACIMA DA TABELA",IF(N31<-Resumo!$B$4,"ABAIXO DA TABELA","OK"))) -> OK
A32: NF-100031 | B32: CTE-0000030 | C32: TransLog Express | D32: 46040 | E32: =MONTH(D32) -> 1 | F32: R05 | G32: Campinas/SP | H32: Porto Alegre/RS | I32: 382.9 | J32: 1.96 | K32: 192 | L32: 750.78 | M32: =IF(J32="","",ROUND(MAX(I32*J32,K32),2)) -> 750.48 | N32: =IF(M32="","",ROUND(L32-M32,2)) -> 0.3 | O32: =IF(M32="","",N32/M32) -> 0.00039974416 | P32: =IF(M32="","SEM TARIFA NO CONTRATO",IF(N32>Resumo!$B$4,"ACIMA DA TABELA",IF(N32<-Resumo!$B$4,"ABAIXO DA TABELA","OK"))) -> OK
A33: NF-100032 | B33: CTE-0000031 | C33: Norte Sul Fretes | D33: 46040 | E33: =MONTH(D33) -> 1 | F33: R08 | G33: Campinas/SP | H33: Goiânia/GO | I33: 611.9 | J33: 1.553 | K33: 157.87 | L33: 950 | M33: =IF(J33="","",ROUND(MAX(I33*J33,K33),2)) -> 950.28 | N33: =IF(M33="","",ROUND(L33-M33,2)) -> -0.28 | O33: =IF(M33="","",N33/M33) -> -0.00029465 | P33: =IF(M33="","SEM TARIFA NO CONTRATO",IF(N33>Resumo!$B$4,"ACIMA DA TABELA",IF(N33<-Resumo!$B$4,"ABAIXO DA TABELA","OK"))) -> OK
A34: NF-100033 | B34: CTE-0000032 | C34: TransLog Express | D34: 46040 | E34: =MONTH(D34) -> 1 | F34: R01 | G34: Campinas/SP | H34: São Paulo/SP | I34: 309.6 | J34: 0.36 | K34: 72 | L34: 111.82 | M34: =IF(J34="","",ROUND(MAX(I34*J34,K34),2)) -> 111.46 | N34: =IF(M34="","",ROUND(L34-M34,2)) -> 0.36 | O34: =IF(M34="","",N34/M34) -> 0.0032298582 | P34: =IF(M34="","SEM TARIFA NO CONTRATO",IF(N34>Resumo!$B$4,"ACIMA DA TABELA",IF(N34<-Resumo!$B$4,"ABAIXO DA TABELA","OK"))) -> OK
A35: NF-100034 | B35: CTE-0000033 | C35: RodoFácil Transportes | D35: 46040 | E35: =MONTH(D35) -> 1 | F35: R02 | G35: Campinas/SP | H35: Rio de Janeiro/RJ | I35: 1206.8 | J35: 0.95 | K35: 114 | L35: 1146.62 | M35: =IF(J35="","",ROUND(MAX(I35*J35,K35),2)) -> 1146.46 | N35: =IF(M35="","",ROUND(L35-M35,2)) -> 0.16 | O35: =IF(M35="","",N35/M35) -> 0.00013956004 | P35: =IF(M35="","SEM TARIFA NO CONTRATO",IF(N35>Resumo!$B$4,"ACIMA DA TABELA",IF(N35<-Resumo!$B$4,"ABAIXO DA TABELA","OK"))) -> OK
A36: NF-100035 | B36: CTE-0000034 | C36: Norte Sul Fretes | D36: 46040 | E36: =MONTH(D36) -> 1 | F36: R01 | G36: Campinas/SP | H36: São Paulo/SP | I36: 318.2 | J36: 0.3312 | K36: 66.24 | L36: 99.67 | M36: =IF(J36="","",ROUND(MAX(I36*J36,K36),2)) -> 105.39 | N36: =IF(M36="","",ROUND(L36-M36,2)) -> -5.72 | O36: =IF(M36="","",N36/M36) -> -0.054274599 | P36: =IF(M36="","SEM TARIFA NO CONTRATO",IF(N36>Resumo!$B$4,"ACIMA DA TABELA",IF(N36<-Resumo!$B$4,"ABAIXO DA TABELA","OK"))) -> ABAIXO DA TABELA
... A59: NF-100058 | B59: CTE-0000057 | C59: Atlântico Logística | D59: 46052 | E59: =MONTH(D59) -> 1 | F59: R10 | G59: Curitiba/PR | H59: Porto Alegre/RS | I59: 973.2 | J59: 1.386 | K59: 151.2 | L59: 1468.4 | M59: =IF(J59="","",ROUND(MAX(I59*J59,K59),2)) -> 1348.86 | N59: =IF(M59="","",ROUND(L59-M59,2)) -> 119.54 | O59: =IF(M59="","",N59/M59) -> 0.088622985 | P59: =IF(M59="","SEM TARIFA NO CONTRATO",IF(N59>Resumo!$B$4,"ACIMA DA TABELA",IF(N59<-Resumo!$B$4,"ABAIXO DA TABELA","OK"))) -> ACIMA DA TABELA
A60: NF-100059 | B60: CTE-0000058 | C60: Veloz Cargas | D60: 46052 | E60: =MONTH(D60) -> 1 | F60: R10 | G60: Curitiba/PR | H60: Porto Alegre/RS | I60: 558.4 | L60: 921.36 | M60: =IF(J60="","",ROUND(MAX(I60*J60,K60),2)) | N60: =IF(M60="","",ROUND(L60-M60,2)) | O60: =IF(M60="","",N60/M60) | P60: =IF(M60="","SEM TARIFA NO CONTRATO",IF(N60>Resumo!$B$4,"ACIMA DA TABELA",IF(N60<-Resumo!$B$4,"ABAIXO DA TABELA","OK"))) -> SEM TARIFA NO CONTRATO
A61: NF-100060 | B61: CTE-0000059 | C61: RodoFácil Transportes | D61: 46053 | E61: =MONTH(D61) -> 1 | F61: R09 | G61: Curitiba/PR | H61: São Paulo/SP | I61: 199.7 | J61: 0.8132 | K61: 103.74 | L61: 162.37 | M61: =IF(J61="","",ROUND(MAX(I61*J61,K61),2)) -> 162.4 | N61: =IF(M61="","",ROUND(L61-M61,2)) -> -0.03 | O61: =IF(M61="","",N61/M61) -> -0.00018472906 | P61: =IF(M61="","SEM TARIFA NO CONTRATO",IF(N61>Resumo!$B$4,"ACIMA DA TABELA",IF(N61<-Resumo!$B$4,"ABAIXO DA TABELA","OK"))) -> OK
A62: NF-100061 | B62: CTE-0000060 | C62: TransLog Express | D62: 46053 | E62: =MONTH(D62) -> 1 | F62: R04 | G62: Campinas/SP | H62: Curitiba/PR | I62: 129.1 | J62: 0.856 | K62: 109.2 | L62: 110.77 | M62: =IF(J62="","",ROUND(MAX(I62*J62,K62),2)) -> 110.51 | N62: =IF(M62="","",ROUND(L62-M62,2)) -> 0.26 | O62: =IF(M62="","",N62/M62) -> 0.0023527283 | P62: =IF(M62="","SEM TARIFA NO CONTRATO",IF(N62>Resumo!$B$4,"ACIMA DA TABELA",IF(N62<-Resumo!$B$4,"ABAIXO DA TABELA","OK"))) -> OK
A63: NF-100062 | B63: CTE-0000061 | C63: Veloz Cargas | D63: 46053 | E63: =MONTH(D63) -> 1 | F63: R05 | G63: Campinas/SP | H63: Porto Alegre/RS | I63: 2187.7 | J63: 2.156 | K63: 211.2 | L63: 5646.19 | M63: =IF(J63="","",ROUND(MAX(I63*J63,K63),2)) -> 4716.68 | N63: =IF(M63="","",ROUND(L63-M63,2)) -> 929.51 | O63: =IF(M63="","",N63/M63) -> 0.1970687 | P63: =IF(M63="","SEM TARIFA NO CONTRATO",IF(N63>Resumo!$B$4,"ACIMA DA TABELA",IF(N63<-Resumo!$B$4,"ABAIXO DA TABELA","OK"))) -> ACIMA DA TABELA
A64: NF-100063 | B64: CTE-0000062 | C64: Norte Sul Fretes | D64: 46054 | E64: =MONTH(D64) -> 2 | F64: R09 | G64: Curitiba/PR | H64: São Paulo/SP | I64: 953.5 | J64: 0.7875 | K64: 100.46 | L64: 750.93 | M64: =IF(J64="","",ROUND(MAX(I64*J64,K64),2)) -> 750.88 | N64: =IF(M64="","",ROUND(L64-M64,2)) -> 0.05 | O64: =IF(M64="","",N64/M64) -> 6.6588536e-05 | P64: =IF(M64="","SEM TARIFA NO CONTRATO",IF(N64>Resumo!$B$4,"ACIMA DA TABELA",IF(N64<-Resumo!$B$4,"ABAIXO DA TABELA","OK"))) -> OK
A65: NF-100064 | B65: CTE-0000063 | C65: Veloz Cargas | D65: 46055 | E65: =MONTH(D65) -> 2 | F65: R02 | G65: Campinas/SP | H65: Rio de Janeiro/RJ | I65: 275.5 | J65: 1.1 | K65: 132 | L65: 303.14 | M65: =IF(J65="","",ROUND(MAX(I65*J65,K65),2)) -> 303.05 | N65: =IF(M65="","",ROUND(L65-M65,2)) -> 0.09 | O65: =IF(M65="","",N65/M65) -> 0.0002969807 | P65: =IF(M65="","SEM TARIFA NO CONTRATO",IF(N65>Resumo!$B$4,"ACIMA DA TABELA",IF(N65<-Resumo!$B$4,"ABAIXO DA TABELA","OK"))) -> OK
A66: NF-100065 | B66: CTE-0000064 | C66: Veloz Cargas | D66: 46056 | E66: =MONTH(D66) -> 2 | F66: R02 | G66: Campinas/SP | H66: Rio de Janeiro/RJ | I66: 1004.7 | J66: 1.1 | K66: 132 | L66: 1105.39 | M66: =IF(J66="","",ROUND(MAX(I66*J66,K66),2)) -> 1105.17 | N66: =IF(M66="","",ROUND(L66-M66,2)) -> 0.22 | O66: =IF(M66="","",N66/M66) -> 0.0001990644 | P66: =IF(M66="","SEM TARIFA NO CONTRATO",IF(N66>Resumo!$B$4,"ACIMA DA TABELA",IF(N66<-Resumo!$B$4,"ABAIXO DA TABELA","OK"))) -> OK
A67: NF-100066 | B67: CTE-0000065 | C67: TransLog Express | D67: 46058 | E67: =MONTH(D67) -> 2 | F67: R01 | G67: Campinas/SP | H67: São Paulo/SP | I67: 2042.1 | J67: 0.36 | K67: 72 | L67: 734.99 | M67: =IF(J67="","",ROUND(MAX(I67*J67,K67),2)) -> 735.16 | N67: =IF(M67="","",ROUND(L67-M67,2)) -> -0.17 | O67: =IF(M67="","",N67/M67) -> -0.00023124218 | P67: =IF(M67="","SEM TARIFA NO CONTRATO",IF(N67>Resumo!$B$4,"ACIMA DA TABELA",IF(N67<-Resumo!$B$4,"ABAIXO DA TABELA","OK"))) -> OK
A68: NF-100067 | B68: CTE-0000066 | C68: RodoFácil Transportes | D68: 46058 | E68: =MONTH(D68) -> 2 | F68: R03 | G68: Campinas/SP | H68: Belo Horizonte/MG | I68: 372.3 | J68: 1.0868 | K68: 124.26 | L68: 404.72 | M68: =IF(J68="","",ROUND(MAX(I68*J68,K68),2)) -> 404.62 | N68: =IF(M68="","",ROUND(L68-M68,2)) -> 0.1 | O68: =IF(M68="","",N68/M68) -> 0.00024714547 | P68: =IF(M68="","SEM TARIFA NO CONTRATO",IF(N68>Resumo!$B$4,"ACIMA DA TABELA",IF(N68<-Resumo!$B$4,"ABAIXO DA TABELA","OK"))) -> OK
A69: NF-100068 | B69: CTE-0000067 | C69: TransLog Express | D69: 46058 | E69: =MONTH(D69) -> 2 | F69: R09 | G69: Curitiba/PR | H69: São Paulo/SP | I69: 2073.3 | J69: 0.856 | K69: 109.2 | L69: 1774.93 | M69: =IF(J69="","",ROUND(MAX(I69*J69,K69),2)) -> 1774.74 | N69: =IF(M69="","",ROUND(L69-M69,2)) -> 0.19 | O69: =IF(M69="","",N69/M69) -> 0.00010705794 | P69: =IF(M69="","SEM TARIFA NO CONTRATO",IF(N69>Resumo!$B$4,"ACIMA DA TABELA",IF(N69<-Resumo!$B$4,"ABAIXO DA TABELA","OK"))) -> OK
A70: NF-100069 | B70: CTE-0000068 | C70: TransLog Express | D70: 46059 | E70: =MONTH(D70) -> 2 | F70: R01 | G70: Campinas/SP | H70: São Paulo/SP | I70: 467.2 | J70: 0.36 | K70: 72 | L70: 167.89 | M70: =IF(J70="","",ROUND(MAX(I70*J70,K70),2)) -> 168.19 | N70: =IF(M70="","",ROUND(L70-M70,2)) -> -0.3 | O70: =IF(M70="","",N70/M70) -> -0.001783697 | P70: =IF(M70="","SEM TARIFA NO CONTRATO",IF(N70>Resumo!$B$4,"ACIMA DA TABELA",IF(N70<-Resumo!$B$4,"ABAIXO DA TABELA","OK"))) -> OK
A71: NF-100070 | B71: CTE-0000069 | C71: Veloz Cargas | D71: 46060 | E71: =MONTH(D71) -> 2 | F71: R02 | G71: Campinas/SP | H71: Rio de Janeiro/RJ | I71: 554.2 | J71: 1.1 | K71: 132 | L71: 609.33 | M71: =IF(J71="","",ROUND(MAX(I71*J71,K71),2)) -> 609.62 | N71: =IF(M71="","",ROUND(L71-M71,2)) -> -0.29 | O71: =IF(M71="","",N71/M71) -> -0.00047570618 | P71: =IF(M71="","SEM TARIFA NO CONTRATO",IF(N71>Resumo!$B$4,"ACIMA DA TABELA",IF(N71<-Resumo!$B$4,"ABAIXO DA TABELA","OK"))) -> OK
...

Sheet Duplicidades
A1: CT-e | B1: Qtd. faturas | C1: Faturas | D1: Transportadora | E1: Total cobrado (R$) | F1: Valor a mais (R$)
A2: CTE-0000495 | B2: 2 | C2: NF-100501 | NF-100507 | D2: Veloz Cargas | E2: 6618.52 | F2: 3309.26
A3: CTE-0000377 | B3: 2 | C3: NF-100381 | NF-100383 | D3: Atlântico Logística | E3: 2630.38 | F3: 1315.19
A4: CTE-0000506 | B4: 2 | C4: NF-100513 | NF-100521 | D4: RodoFácil Transportes | E4: 936.24 | F4: 468.12
A5: CTE-0000123 | B5: 2 | C5: NF-100125 | NF-100138 | D5: TransLog Express | E5: 806.04 | F5: 403.02
A6: CTE-0000101 | B6: 2 | C6: NF-100102 | NF-100110 | D6: TransLog Express | E6: 698.44 | F6: 349.22
A7: CTE-0000372 | B7: 2 | C7: NF-100375 | NF-100386 | D7: Veloz Cargas | E7: 649.56 | F7: 324.78
A8: CTE-0000022 | B8: 2 | C8: NF-100022 | NF-100029 | D8: Veloz Cargas | E8: 406.88 | F8: 203.44
A9: CTE-0000365 | B9: 2 | C9: NF-100368 | NF-100379 | D9: TransLog Express | E9: 186.26 | F9: 93.13
A11: Fonte: view vw_duplicidades (sql/02_auditoria.sql). 'Valor a mais' = total cobrado menos uma cobrança.
